[2023-10-07T04:27:27.772+0000] {taskinstance.py:1157} INFO - Dependencies all met for dep_context=non-requeueable deps ti=<TaskInstance: data_reading_dag.reading_data manual__2023-10-07T04:27:25.034684+00:00 [queued]>
[2023-10-07T04:27:27.784+0000] {taskinstance.py:1157} INFO - Dependencies all met for dep_context=requeueable deps ti=<TaskInstance: data_reading_dag.reading_data manual__2023-10-07T04:27:25.034684+00:00 [queued]>
[2023-10-07T04:27:27.786+0000] {taskinstance.py:1359} INFO - Starting attempt 1 of 1
[2023-10-07T04:27:27.812+0000] {taskinstance.py:1380} INFO - Executing <Task(PythonOperator): reading_data> on 2023-10-07 04:27:25.034684+00:00
[2023-10-07T04:27:27.822+0000] {standard_task_runner.py:57} INFO - Started process 88 to run task
[2023-10-07T04:27:27.826+0000] {standard_task_runner.py:84} INFO - Running: ['***', 'tasks', 'run', 'data_reading_dag', 'reading_data', 'manual__2023-10-07T04:27:25.034684+00:00', '--job-id', '11', '--raw', '--subdir', 'DAGS_FOLDER/read_db_by_plain_python.py', '--cfg-path', '/tmp/tmpo4a_i_xx']
[2023-10-07T04:27:27.828+0000] {standard_task_runner.py:85} INFO - Job 11: Subtask reading_data
[2023-10-07T04:27:27.903+0000] {task_command.py:415} INFO - Running <TaskInstance: data_reading_dag.reading_data manual__2023-10-07T04:27:25.034684+00:00 [running]> on host 14ef8d95b0cd
[2023-10-07T04:27:28.002+0000] {taskinstance.py:1660} INFO - Exporting env vars: AIRFLOW_CTX_DAG_EMAIL='***@example.com' AIRFLOW_CTX_DAG_OWNER='***' AIRFLOW_CTX_DAG_ID='data_reading_dag' AIRFLOW_CTX_TASK_ID='reading_data' AIRFLOW_CTX_EXECUTION_DATE='2023-10-07T04:27:25.034684+00:00' AIRFLOW_CTX_TRY_NUMBER='1' AIRFLOW_CTX_DAG_RUN_ID='manual__2023-10-07T04:27:25.034684+00:00'
[2023-10-07T04:27:28.076+0000] {taskinstance.py:1935} ERROR - Task failed with exception
Traceback (most recent call last):
  File "/home/airflow/.local/lib/python3.8/site-packages/mysql/connector/connection_cext.py", line 633, in cmd_query
    self._cmysql.query(
_mysql_connector.MySQLInterfaceError: Table 'homestead.customers' doesn't exist

The above exception was the direct cause of the following exception:

Traceback (most recent call last):
  File "/home/airflow/.local/lib/python3.8/site-packages/airflow/operators/python.py", line 192, in execute
    return_value = self.execute_callable()
  File "/home/airflow/.local/lib/python3.8/site-packages/airflow/operators/python.py", line 209, in execute_callable
    return self.python_callable(*self.op_args, **self.op_kwargs)
  File "/opt/airflow/dags/read_db_by_plain_python.py", line 16, in reading_data
    mycursor.execute("SELECT * FROM customers")
  File "/home/airflow/.local/lib/python3.8/site-packages/mysql/connector/cursor_cext.py", line 330, in execute
    result = self._cnx.cmd_query(
  File "/home/airflow/.local/lib/python3.8/site-packages/mysql/connector/opentelemetry/context_propagation.py", line 86, in wrapper
    result = method(cnx, *args, **kwargs)
  File "/home/airflow/.local/lib/python3.8/site-packages/mysql/connector/connection_cext.py", line 641, in cmd_query
    raise get_mysql_exception(
mysql.connector.errors.ProgrammingError: 1146 (42S02): Table 'homestead.customers' doesn't exist
[2023-10-07T04:27:28.094+0000] {taskinstance.py:1398} INFO - Marking task as FAILED. dag_id=data_reading_dag, task_id=reading_data, execution_date=20231007T042725, start_date=20231007T042727, end_date=20231007T042728
[2023-10-07T04:27:28.107+0000] {warnings.py:109} WARNING - /home/***/.local/lib/python3.8/site-packages/***/utils/email.py:154: RemovedInAirflow3Warning: Fetching SMTP credentials from configuration variables will be deprecated in a future release. Please set credentials using a connection instead.
  send_mime_email(e_from=mail_from, e_to=recipients, mime_msg=msg, conn_id=conn_id, dryrun=dryrun)

[2023-10-07T04:27:28.109+0000] {configuration.py:1063} WARNING - section/key [smtp/smtp_user] not found in config
[2023-10-07T04:27:28.110+0000] {email.py:270} INFO - Email alerting: attempt 1
[2023-10-07T04:27:28.121+0000] {configuration.py:1063} WARNING - section/key [smtp/smtp_user] not found in config
[2023-10-07T04:27:28.122+0000] {email.py:270} INFO - Email alerting: attempt 1
[2023-10-07T04:27:28.123+0000] {taskinstance.py:2005} ERROR - Failed to send email to: ['***@example.com']
Traceback (most recent call last):
  File "/home/airflow/.local/lib/python3.8/site-packages/mysql/connector/connection_cext.py", line 633, in cmd_query
    self._cmysql.query(
_mysql_connector.MySQLInterfaceError: Table 'homestead.customers' doesn't exist

The above exception was the direct cause of the following exception:

Traceback (most recent call last):
  File "/home/airflow/.local/lib/python3.8/site-packages/airflow/models/taskinstance.py", line 1516, in _run_raw_task
    self._execute_task_with_callbacks(context, test_mode, session=session)
  File "/home/airflow/.local/lib/python3.8/site-packages/airflow/models/taskinstance.py", line 1679, in _execute_task_with_callbacks
    result = self._execute_task(context, task_orig)
  File "/home/airflow/.local/lib/python3.8/site-packages/airflow/models/taskinstance.py", line 1742, in _execute_task
    result = execute_callable(context=context, **execute_callable_kwargs)
  File "/home/airflow/.local/lib/python3.8/site-packages/airflow/operators/python.py", line 192, in execute
    return_value = self.execute_callable()
  File "/home/airflow/.local/lib/python3.8/site-packages/airflow/operators/python.py", line 209, in execute_callable
    return self.python_callable(*self.op_args, **self.op_kwargs)
  File "/opt/airflow/dags/read_db_by_plain_python.py", line 16, in reading_data
    mycursor.execute("SELECT * FROM customers")
  File "/home/airflow/.local/lib/python3.8/site-packages/mysql/connector/cursor_cext.py", line 330, in execute
    result = self._cnx.cmd_query(
  File "/home/airflow/.local/lib/python3.8/site-packages/mysql/connector/opentelemetry/context_propagation.py", line 86, in wrapper
    result = method(cnx, *args, **kwargs)
  File "/home/airflow/.local/lib/python3.8/site-packages/mysql/connector/connection_cext.py", line 641, in cmd_query
    raise get_mysql_exception(
mysql.connector.errors.ProgrammingError: 1146 (42S02): Table 'homestead.customers' doesn't exist

During handling of the above exception, another exception occurred:

Traceback (most recent call last):
  File "/home/airflow/.local/lib/python3.8/site-packages/airflow/models/taskinstance.py", line 2418, in email_alert
    send_email(task.email, subject, html_content)
  File "/home/airflow/.local/lib/python3.8/site-packages/airflow/utils/email.py", line 80, in send_email
    return backend(
  File "/home/airflow/.local/lib/python3.8/site-packages/airflow/utils/email.py", line 154, in send_email_smtp
    send_mime_email(e_from=mail_from, e_to=recipients, mime_msg=msg, conn_id=conn_id, dryrun=dryrun)
  File "/home/airflow/.local/lib/python3.8/site-packages/airflow/utils/email.py", line 272, in send_mime_email
    smtp_conn = _get_smtp_connection(smtp_host, smtp_port, smtp_timeout, smtp_ssl)
  File "/home/airflow/.local/lib/python3.8/site-packages/airflow/utils/email.py", line 317, in _get_smtp_connection
    return smtplib.SMTP(host=host, port=port, timeout=timeout)
  File "/usr/local/lib/python3.8/smtplib.py", line 255, in __init__
    (code, msg) = self.connect(host, port)
  File "/usr/local/lib/python3.8/smtplib.py", line 339, in connect
    self.sock = self._get_socket(host, port, self.timeout)
  File "/usr/local/lib/python3.8/smtplib.py", line 310, in _get_socket
    return socket.create_connection((host, port), timeout,
  File "/usr/local/lib/python3.8/socket.py", line 808, in create_connection
    raise err
  File "/usr/local/lib/python3.8/socket.py", line 796, in create_connection
    sock.connect(sa)
OSError: [Errno 99] Cannot assign requested address

During handling of the above exception, another exception occurred:

Traceback (most recent call last):
  File "/home/airflow/.local/lib/python3.8/site-packages/airflow/models/taskinstance.py", line 2003, in handle_failure
    self.email_alert(error, task)
  File "/home/airflow/.local/lib/python3.8/site-packages/airflow/models/taskinstance.py", line 2420, in email_alert
    send_email(task.email, subject, html_content_err)
  File "/home/airflow/.local/lib/python3.8/site-packages/airflow/utils/email.py", line 80, in send_email
    return backend(
  File "/home/airflow/.local/lib/python3.8/site-packages/airflow/utils/email.py", line 154, in send_email_smtp
    send_mime_email(e_from=mail_from, e_to=recipients, mime_msg=msg, conn_id=conn_id, dryrun=dryrun)
  File "/home/airflow/.local/lib/python3.8/site-packages/airflow/utils/email.py", line 272, in send_mime_email
    smtp_conn = _get_smtp_connection(smtp_host, smtp_port, smtp_timeout, smtp_ssl)
  File "/home/airflow/.local/lib/python3.8/site-packages/airflow/utils/email.py", line 317, in _get_smtp_connection
    return smtplib.SMTP(host=host, port=port, timeout=timeout)
  File "/usr/local/lib/python3.8/smtplib.py", line 255, in __init__
    (code, msg) = self.connect(host, port)
  File "/usr/local/lib/python3.8/smtplib.py", line 339, in connect
    self.sock = self._get_socket(host, port, self.timeout)
  File "/usr/local/lib/python3.8/smtplib.py", line 310, in _get_socket
    return socket.create_connection((host, port), timeout,
  File "/usr/local/lib/python3.8/socket.py", line 808, in create_connection
    raise err
  File "/usr/local/lib/python3.8/socket.py", line 796, in create_connection
    sock.connect(sa)
OSError: [Errno 99] Cannot assign requested address
[2023-10-07T04:27:28.149+0000] {standard_task_runner.py:104} ERROR - Failed to execute job 11 for task reading_data (1146 (42S02): Table 'homestead.customers' doesn't exist; 88)
[2023-10-07T04:27:28.200+0000] {local_task_job_runner.py:228} INFO - Task exited with return code 1
[2023-10-07T04:27:28.219+0000] {taskinstance.py:2776} INFO - 0 downstream tasks scheduled from follow-on schedule check
