[2023-10-14T03:42:02.221+0000] {taskinstance.py:1157} INFO - Dependencies all met for dep_context=non-requeueable deps ti=<TaskInstance: example_pipeline.read_db scheduled__2023-10-14T03:41:00+00:00 [queued]>
[2023-10-14T03:42:02.227+0000] {taskinstance.py:1157} INFO - Dependencies all met for dep_context=requeueable deps ti=<TaskInstance: example_pipeline.read_db scheduled__2023-10-14T03:41:00+00:00 [queued]>
[2023-10-14T03:42:02.228+0000] {taskinstance.py:1359} INFO - Starting attempt 1 of 1
[2023-10-14T03:42:02.240+0000] {taskinstance.py:1380} INFO - Executing <Task(PythonOperator): read_db> on 2023-10-14 03:41:00+00:00
[2023-10-14T03:42:02.244+0000] {standard_task_runner.py:57} INFO - Started process 390 to run task
[2023-10-14T03:42:02.246+0000] {standard_task_runner.py:84} INFO - Running: ['***', 'tasks', 'run', 'example_pipeline', 'read_db', 'scheduled__2023-10-14T03:41:00+00:00', '--job-id', '145', '--raw', '--subdir', 'DAGS_FOLDER/data_ingestion_lab.py', '--cfg-path', '/tmp/tmp0frfkim7']
[2023-10-14T03:42:02.248+0000] {standard_task_runner.py:85} INFO - Job 145: Subtask read_db
[2023-10-14T03:42:02.284+0000] {task_command.py:415} INFO - Running <TaskInstance: example_pipeline.read_db scheduled__2023-10-14T03:41:00+00:00 [running]> on host 89ffa62682cc
[2023-10-14T03:42:02.435+0000] {taskinstance.py:1660} INFO - Exporting env vars: AIRFLOW_CTX_DAG_EMAIL='***@example.com' AIRFLOW_CTX_DAG_OWNER='***' AIRFLOW_CTX_DAG_ID='example_pipeline' AIRFLOW_CTX_TASK_ID='read_db' AIRFLOW_CTX_EXECUTION_DATE='2023-10-14T03:41:00+00:00' AIRFLOW_CTX_TRY_NUMBER='1' AIRFLOW_CTX_DAG_RUN_ID='scheduled__2023-10-14T03:41:00+00:00'
[2023-10-14T03:42:02.440+0000] {base.py:73} INFO - Using connection ID 'mydb' for task execution.
[2023-10-14T03:42:02.447+0000] {taskinstance.py:1935} ERROR - Task failed with exception
Traceback (most recent call last):
  File "/home/airflow/.local/lib/python3.8/site-packages/airflow/operators/python.py", line 192, in execute
    return_value = self.execute_callable()
  File "/home/airflow/.local/lib/python3.8/site-packages/airflow/operators/python.py", line 209, in execute_callable
    return self.python_callable(*self.op_args, **self.op_kwargs)
  File "/opt/airflow/dags/data_ingestion_lab.py", line 21, in ingest_data
    connection = mysql_hook.get_conn()
  File "/home/airflow/.local/lib/python3.8/site-packages/airflow/providers/mysql/hooks/mysql.py", line 194, in get_conn
    return MySQLdb.connect(**conn_config)
  File "/home/airflow/.local/lib/python3.8/site-packages/MySQLdb/__init__.py", line 121, in Connect
    return Connection(*args, **kwargs)
  File "/home/airflow/.local/lib/python3.8/site-packages/MySQLdb/connections.py", line 193, in __init__
    super().__init__(*args, **kwargs2)
MySQLdb.OperationalError: (1045, "Access denied for user '***'@'172.18.0.9' (using password: YES)")
[2023-10-14T03:42:02.455+0000] {taskinstance.py:1398} INFO - Marking task as FAILED. dag_id=example_pipeline, task_id=read_db, execution_date=20231014T034100, start_date=20231014T034202, end_date=20231014T034202
[2023-10-14T03:42:02.463+0000] {warnings.py:109} WARNING - /home/***/.local/lib/python3.8/site-packages/***/utils/email.py:154: RemovedInAirflow3Warning: Fetching SMTP credentials from configuration variables will be deprecated in a future release. Please set credentials using a connection instead.
  send_mime_email(e_from=mail_from, e_to=recipients, mime_msg=msg, conn_id=conn_id, dryrun=dryrun)

[2023-10-14T03:42:02.464+0000] {configuration.py:1063} WARNING - section/key [smtp/smtp_user] not found in config
[2023-10-14T03:42:02.464+0000] {email.py:270} INFO - Email alerting: attempt 1
[2023-10-14T03:42:02.468+0000] {configuration.py:1063} WARNING - section/key [smtp/smtp_user] not found in config
[2023-10-14T03:42:02.469+0000] {email.py:270} INFO - Email alerting: attempt 1
[2023-10-14T03:42:02.469+0000] {taskinstance.py:2005} ERROR - Failed to send email to: ['***@example.com']
Traceback (most recent call last):
  File "/home/airflow/.local/lib/python3.8/site-packages/airflow/models/taskinstance.py", line 1516, in _run_raw_task
    self._execute_task_with_callbacks(context, test_mode, session=session)
  File "/home/airflow/.local/lib/python3.8/site-packages/airflow/models/taskinstance.py", line 1679, in _execute_task_with_callbacks
    result = self._execute_task(context, task_orig)
  File "/home/airflow/.local/lib/python3.8/site-packages/airflow/models/taskinstance.py", line 1742, in _execute_task
    result = execute_callable(context=context, **execute_callable_kwargs)
  File "/home/airflow/.local/lib/python3.8/site-packages/airflow/operators/python.py", line 192, in execute
    return_value = self.execute_callable()
  File "/home/airflow/.local/lib/python3.8/site-packages/airflow/operators/python.py", line 209, in execute_callable
    return self.python_callable(*self.op_args, **self.op_kwargs)
  File "/opt/airflow/dags/data_ingestion_lab.py", line 21, in ingest_data
    connection = mysql_hook.get_conn()
  File "/home/airflow/.local/lib/python3.8/site-packages/airflow/providers/mysql/hooks/mysql.py", line 194, in get_conn
    return MySQLdb.connect(**conn_config)
  File "/home/airflow/.local/lib/python3.8/site-packages/MySQLdb/__init__.py", line 121, in Connect
    return Connection(*args, **kwargs)
  File "/home/airflow/.local/lib/python3.8/site-packages/MySQLdb/connections.py", line 193, in __init__
    super().__init__(*args, **kwargs2)
MySQLdb.OperationalError: (1045, "Access denied for user '***'@'172.18.0.9' (using password: YES)")

During handling of the above exception, another exception occurred:

Traceback (most recent call last):
  File "/home/airflow/.local/lib/python3.8/site-packages/airflow/models/taskinstance.py", line 2418, in email_alert
    send_email(task.email, subject, html_content)
  File "/home/airflow/.local/lib/python3.8/site-packages/airflow/utils/email.py", line 80, in send_email
    return backend(
  File "/home/airflow/.local/lib/python3.8/site-packages/airflow/utils/email.py", line 154, in send_email_smtp
    send_mime_email(e_from=mail_from, e_to=recipients, mime_msg=msg, conn_id=conn_id, dryrun=dryrun)
  File "/home/airflow/.local/lib/python3.8/site-packages/airflow/utils/email.py", line 272, in send_mime_email
    smtp_conn = _get_smtp_connection(smtp_host, smtp_port, smtp_timeout, smtp_ssl)
  File "/home/airflow/.local/lib/python3.8/site-packages/airflow/utils/email.py", line 317, in _get_smtp_connection
    return smtplib.SMTP(host=host, port=port, timeout=timeout)
  File "/usr/local/lib/python3.8/smtplib.py", line 255, in __init__
    (code, msg) = self.connect(host, port)
  File "/usr/local/lib/python3.8/smtplib.py", line 339, in connect
    self.sock = self._get_socket(host, port, self.timeout)
  File "/usr/local/lib/python3.8/smtplib.py", line 310, in _get_socket
    return socket.create_connection((host, port), timeout,
  File "/usr/local/lib/python3.8/socket.py", line 808, in create_connection
    raise err
  File "/usr/local/lib/python3.8/socket.py", line 796, in create_connection
    sock.connect(sa)
OSError: [Errno 99] Cannot assign requested address

During handling of the above exception, another exception occurred:

Traceback (most recent call last):
  File "/home/airflow/.local/lib/python3.8/site-packages/airflow/models/taskinstance.py", line 2003, in handle_failure
    self.email_alert(error, task)
  File "/home/airflow/.local/lib/python3.8/site-packages/airflow/models/taskinstance.py", line 2420, in email_alert
    send_email(task.email, subject, html_content_err)
  File "/home/airflow/.local/lib/python3.8/site-packages/airflow/utils/email.py", line 80, in send_email
    return backend(
  File "/home/airflow/.local/lib/python3.8/site-packages/airflow/utils/email.py", line 154, in send_email_smtp
    send_mime_email(e_from=mail_from, e_to=recipients, mime_msg=msg, conn_id=conn_id, dryrun=dryrun)
  File "/home/airflow/.local/lib/python3.8/site-packages/airflow/utils/email.py", line 272, in send_mime_email
    smtp_conn = _get_smtp_connection(smtp_host, smtp_port, smtp_timeout, smtp_ssl)
  File "/home/airflow/.local/lib/python3.8/site-packages/airflow/utils/email.py", line 317, in _get_smtp_connection
    return smtplib.SMTP(host=host, port=port, timeout=timeout)
  File "/usr/local/lib/python3.8/smtplib.py", line 255, in __init__
    (code, msg) = self.connect(host, port)
  File "/usr/local/lib/python3.8/smtplib.py", line 339, in connect
    self.sock = self._get_socket(host, port, self.timeout)
  File "/usr/local/lib/python3.8/smtplib.py", line 310, in _get_socket
    return socket.create_connection((host, port), timeout,
  File "/usr/local/lib/python3.8/socket.py", line 808, in create_connection
    raise err
  File "/usr/local/lib/python3.8/socket.py", line 796, in create_connection
    sock.connect(sa)
OSError: [Errno 99] Cannot assign requested address
[2023-10-14T03:42:02.482+0000] {standard_task_runner.py:104} ERROR - Failed to execute job 145 for task read_db ((1045, "Access denied for user '***'@'172.18.0.9' (using password: YES)"); 390)
[2023-10-14T03:42:02.499+0000] {local_task_job_runner.py:228} INFO - Task exited with return code 1
[2023-10-14T03:42:02.513+0000] {taskinstance.py:2776} INFO - 0 downstream tasks scheduled from follow-on schedule check
